<!-- Left Mid Leg -->

<link name="hip_lm_servo">
  <inertial>
    <origin xyz="0 .009388 -0.020962" rpy="0 0 1.570796"/>
    <mass value="0.052637"/>
    <inertia ixx="0.000008677" ixy="0" ixz="0.000000097" iyy="0.000014407" iyz="0" izz="0.000009204"/>
  </inertial>
  <visual name="hip_lm_servo">
    <origin xyz="0 .009388 -0.020962" rpy="0 0 1.570796"/>
    <geometry>
      <mesh filename="package://hex_walker/mesh/servo.stl" scale="1.0 1.0 1.0"/>
    </geometry>
  </visual>
  <collision name="hip_lm_servo_c">
    <origin xyz="0 .009388 -0.020962" rpy="0 0 1.570796"/>
    <geometry>
      <mesh filename="package://hex_walker/mesh/servo.stl" scale="1.0 1.0 1.0"/>
    </geometry>
    <surface>
      <friction>
        <ode>
          <mu>0.85</mu>
          <mu2>0.85</mu2>
        </ode>
      </friction>
    </surface>
  </collision>
</link>

<joint name="lm_servo1" type="revolute">
  <parent link="body"/>
  <child link="hip_lm_servo"/>
  <origin xyz=".13938 0 0.021905" rpy="0 0 0"/>
  <axis xyz="0 0 1"/>
  <limit lower="-1.22173" upper="1.48353" effort="10" velocity="1.5708"/>
</joint>

<transmission name="lm1_trans" type="SimpleTransmission">
  <type>transmission_interface/SimpleTransmission</type>
  <actuator name="lbk_motor">
    <mechanicalReduction>1</mechanicalReduction>
  </actuator>
  <joint name="lm_servo1">
    <hardwareInterface>hardware_interface/PositionJointInterface</hardwareInterface>
  </joint>
</transmission>

 <link name="hip_lm">
   <inertial>
    <origin xyz="0 0 0" rpy="0 0 0"/>
    <mass value="0.033238"/>
    <inertia ixx="0.000012095" ixy="0.000000473" ixz="-0.000000161" iyy="0.000019489" iyz="0.000001093" izz="0.000025287"/>
  </inertial>
  <visual name="hip_lm1">
    <origin xyz="0 0 0" rpy="0 0 0"/>
    <geometry>
      <mesh filename="package://hex_walker/mesh/hip_v1.stl" scale="1.0 1.0 1.0"/>
    </geometry>
  </visual>
  <collision name="hip_lm_c">
    <origin xyz="0 0 0" rpy="0 0 0"/>
    <geometry>
      <mesh filename="package://hex_walker/mesh/hip_v1.stl" scale="1.0 1.0 1.0"/>
    </geometry>
    <surface>
      <friction>
        <ode>
          <mu>0.85</mu>
          <mu2>0.85</mu2>
        </ode>
      </friction>
    </surface>
  </collision>
</link>

<joint name="left_mid_hip_servo_joint" type="fixed">
  <child link="hip_lm"/>
  <parent link="hip_lm_servo"/>
  <origin xyz=".012472 .013122 -.030332" rpy="0 0 1.570796"/>
</joint>

 <link name="midleg_lm_servo1">
  <inertial>
    <origin xyz="-.024605 -.01 0" rpy="-1.570796 0 -1.570796"/>
    <mass value="0.052637"/>
    <inertia ixx="0.000008677" ixy="0" ixz="0.000000097" iyy="0.000014407" iyz="0" izz="0.000009204"/>
  </inertial>
  <visual name="midleg_lm_servo1">
    <origin xyz="-.024605 -.01 0" rpy="-1.570796 0 -1.570796"/>
    <geometry>
      <mesh filename="package://hex_walker/mesh/servo.stl" scale="1.0 1.0 1.0"/>
    </geometry>
  </visual>
  <collision name="midleg_lm_servo1_c">
    <origin xyz="-.024605 -.01 0" rpy="-1.570796 0 -1.570796"/>
    <geometry>
      <mesh filename="package://hex_walker/mesh/servo.stl" scale="1.0 1.0 1.0"/>
    </geometry>
    <surface>
      <friction>
        <ode>
          <mu>0.85</mu>
          <mu2>0.85</mu2>
        </ode>
      </friction>
    </surface>
  </collision>
</link>

<joint name="lm_servo2" type="revolute">
  <parent link="hip_lm"/>
  <child link="midleg_lm_servo1"/>
  <origin xyz=".13938 0 0.021905" rpy="0 0 0"/>
  <axis xyz="1 0 0"/>
  <limit lower="-1.22173" upper="1.48353" effort="10" velocity="1.5708"/>
</joint>

<transmission name="lm2_trans" type="SimpleTransmission">
  <type>transmission_interface/SimpleTransmission</type>
  <actuator name="lbk_motor">
    <mechanicalReduction>1</mechanicalReduction>
  </actuator>
  <joint name="lm_servo2">
    <hardwareInterface>hardware_interface/PositionJointInterface</hardwareInterface>
  </joint>
</transmission>

<link name="midleg_lm">
  <inertial>
    <origin xyz="0 0 0" rpy="0 0 0"/>
    <mass value="0.108"/>
    <inertia ixx="0.0001029" ixy="0.000000127" ixz="-6.3e-11" iyy="0.000013792" iyz="2.07e-10" izz="0.0001075"/>
  </inertial>
  <visual name="midleg_lm1">
    <origin xyz="0 0 0" rpy="0 0 0"/>
    <geometry>
      <mesh filename="package://hex_walker/mesh/midleg_v2.stl" scale="1.0 1.0 1.0"/>
    </geometry>
  </visual>
  <collision name="midleg_lm_c">
    <origin xyz="0 0 0" rpy="0 0 0"/>
    <geometry>
      <mesh filename="package://hex_walker/mesh/midleg_v2.stl" scale="1.0 1.0 1.0"/>
    </geometry>
    <surface>
      <friction>
        <ode>
          <mu>0.85</mu>
          <mu2>0.85</mu2>
        </ode>
      </friction>
    </surface>
  </collision>
</link>

<joint name="lmk1_fixed_joint" type="fixed">
  <parent link="midleg_lm_servo1"/>
  <child link="midleg_lm"/>
  <origin xyz="-.035711 -.037826 0" rpy="0 0 0"/>
</joint>

<link name="midleg_lm_servo2">
  <inertial>
    <origin xyz="0 0 0" rpy="1.570796 0 1.570796"/>
    <mass value="0.052637"/>
    <inertia ixx="0.000008677" ixy="0" ixz="0.000000097" iyy="0.000014407" iyz="0" izz="0.000009204"/>
  </inertial>
  <visual name="midleg_lm_servo2">
    <origin xyz="0 0 0" rpy="1.570796 0 1.570796"/>
    <geometry>
      <mesh filename="package://hex_walker/mesh/servo.stl" scale="1.0 1.0 1.0"/>
    </geometry>
  </visual>
  <collision name="midleg_lm_servo2_c">
    <origin xyz="0 0 0" rpy="1.570796 0 1.570796"/>
    <geometry>
      <mesh filename="package://hex_walker/mesh/servo.stl" scale="1.0 1.0 1.0"/>
    </geometry>
    <surface>
      <friction>
        <ode>
          <mu>0.85</mu>
          <mu2>0.85</mu2>
        </ode>
      </friction>
    </surface>
  </collision>
</link>

<joint name="lmk2_fixed_joint" type="fixed">
  <parent link="midleg_lm"/>
  <child link="midleg_lm_servo2"/>
  <origin xyz=".01125 -.028326 0" rpy="0 0 0"/>
</joint>

<link name="foot_lm">
  <inertial>
    <origin xyz="-.021362 -.006643 -.04585" rpy="0 0 0"/>
    <mass value="0.056267"/>
    <inertia ixx="0.000054442" ixy="-0.00000087" ixz="-0.00000315" iyy="0.000072163" iyz="-0.00000607" izz="0.000023722"/>
  </inertial>
  <visual name="foot_lm1">
    <origin xyz="-.021362 -.006643 -.04585" rpy="0 0 0"/>
    <geometry>
      <mesh filename="package://hex_walker/mesh/footv1.stl" scale="1.0 1.0 1.0"/>
    </geometry>
  </visual>
  <collision name="foot_lm_c">
    <origin xyz="-.021362 -.006643 -.04585" rpy="0 0 0"/>
    <geometry>
      <mesh filename="package://hex_walker/mesh/footv1.stl" scale="1.0 1.0 1.0"/>
    </geometry>
    <surface>
      <friction>
        <ode>
          <mu>0.85</mu>
          <mu2>0.85</mu2>
        </ode>
      </friction>
    </surface>
  </collision>
</link>

<joint name="lm_servo3" type="revolute">
  <origin xyz=".024517 -.009743 .000044" rpy="0 0 0"/>
  <parent link="midleg_lm_servo2"/>
  <child link="foot_lm"/>
  <axis xyz="1 0 0"/>
  <limit lower="-1.22173" upper="1.48353" effort="10" velocity="1.5708"/>
</joint>

<transmission name="lm3_trans" type="SimpleTransmission">
  <type>transmission_interface/SimpleTransmission</type>
  <actuator name="lbk_motor">
    <mechanicalReduction>1</mechanicalReduction>
  </actuator>
  <joint name="lm_servo3">
    <hardwareInterface>hardware_interface/PositionJointInterface</hardwareInterface>
  </joint>
</transmission>
